{
  "metadata": {
    "kernelspec": {
      "name": "python",
      "display_name": "Python (Pyodide)",
      "language": "python"
    },
    "language_info": {
      "codemirror_mode": {
        "name": "python",
        "version": 3
      },
      "file_extension": ".py",
      "mimetype": "text/x-python",
      "name": "python",
      "nbconvert_exporter": "python",
      "pygments_lexer": "ipython3",
      "version": "3.8"
    }
  },
  "nbformat_minor": 4,
  "nbformat": 4,
  "cells": [
    {
      "cell_type": "code",
      "source": "a=10",
      "metadata": {
        "trusted": true
      },
      "outputs": [],
      "execution_count": 1
    },
    {
      "cell_type": "code",
      "source": "a/0",
      "metadata": {
        "trusted": true
      },
      "outputs": [
        {
          "ename": "<class 'ZeroDivisionError'>",
          "evalue": "division by zero",
          "traceback": [
            "\u001b[0;31m---------------------------------------------------------------------------\u001b[0m",
            "\u001b[0;31mZeroDivisionError\u001b[0m                         Traceback (most recent call last)",
            "Cell \u001b[0;32mIn[2], line 1\u001b[0m\n\u001b[0;32m----> 1\u001b[0m \u001b[43ma\u001b[49m\u001b[38;5;241;43m/\u001b[39;49m\u001b[38;5;241;43m0\u001b[39;49m\n",
            "\u001b[0;31mZeroDivisionError\u001b[0m: division by zero"
          ],
          "output_type": "error"
        }
      ],
      "execution_count": 2
    },
    {
      "cell_type": "code",
      "source": "f = open(\"test.txt\", 'r')\nprint(\"this is my print\")",
      "metadata": {
        "trusted": true
      },
      "outputs": [
        {
          "ename": "<class 'FileNotFoundError'>",
          "evalue": "[Errno 44] No such file or directory: 'test.txt'",
          "traceback": [
            "\u001b[0;31m---------------------------------------------------------------------------\u001b[0m",
            "\u001b[0;31mFileNotFoundError\u001b[0m                         Traceback (most recent call last)",
            "Cell \u001b[0;32mIn[4], line 1\u001b[0m\n\u001b[0;32m----> 1\u001b[0m f \u001b[38;5;241m=\u001b[39m \u001b[38;5;28;43mopen\u001b[39;49m\u001b[43m(\u001b[49m\u001b[38;5;124;43m\"\u001b[39;49m\u001b[38;5;124;43mtest.txt\u001b[39;49m\u001b[38;5;124;43m\"\u001b[39;49m\u001b[43m,\u001b[49m\u001b[43m \u001b[49m\u001b[38;5;124;43m'\u001b[39;49m\u001b[38;5;124;43mr\u001b[39;49m\u001b[38;5;124;43m'\u001b[39;49m\u001b[43m)\u001b[49m\n\u001b[1;32m      2\u001b[0m \u001b[38;5;28mprint\u001b[39m(\u001b[38;5;124m\"\u001b[39m\u001b[38;5;124mthis is my print\u001b[39m\u001b[38;5;124m\"\u001b[39m)\n",
            "File \u001b[0;32m/lib/python3.11/site-packages/IPython/core/interactiveshell.py:310\u001b[0m, in \u001b[0;36m_modified_open\u001b[0;34m(file, *args, **kwargs)\u001b[0m\n\u001b[1;32m    303\u001b[0m \u001b[38;5;28;01mif\u001b[39;00m file \u001b[38;5;129;01min\u001b[39;00m {\u001b[38;5;241m0\u001b[39m, \u001b[38;5;241m1\u001b[39m, \u001b[38;5;241m2\u001b[39m}:\n\u001b[1;32m    304\u001b[0m     \u001b[38;5;28;01mraise\u001b[39;00m \u001b[38;5;167;01mValueError\u001b[39;00m(\n\u001b[1;32m    305\u001b[0m         \u001b[38;5;124mf\u001b[39m\u001b[38;5;124m\"\u001b[39m\u001b[38;5;124mIPython won\u001b[39m\u001b[38;5;124m'\u001b[39m\u001b[38;5;124mt let you open fd=\u001b[39m\u001b[38;5;132;01m{\u001b[39;00mfile\u001b[38;5;132;01m}\u001b[39;00m\u001b[38;5;124m by default \u001b[39m\u001b[38;5;124m\"\u001b[39m\n\u001b[1;32m    306\u001b[0m         \u001b[38;5;124m\"\u001b[39m\u001b[38;5;124mas it is likely to crash IPython. If you know what you are doing, \u001b[39m\u001b[38;5;124m\"\u001b[39m\n\u001b[1;32m    307\u001b[0m         \u001b[38;5;124m\"\u001b[39m\u001b[38;5;124myou can use builtins\u001b[39m\u001b[38;5;124m'\u001b[39m\u001b[38;5;124m open.\u001b[39m\u001b[38;5;124m\"\u001b[39m\n\u001b[1;32m    308\u001b[0m     )\n\u001b[0;32m--> 310\u001b[0m \u001b[38;5;28;01mreturn\u001b[39;00m \u001b[43mio_open\u001b[49m\u001b[43m(\u001b[49m\u001b[43mfile\u001b[49m\u001b[43m,\u001b[49m\u001b[43m \u001b[49m\u001b[38;5;241;43m*\u001b[39;49m\u001b[43margs\u001b[49m\u001b[43m,\u001b[49m\u001b[43m \u001b[49m\u001b[38;5;241;43m*\u001b[39;49m\u001b[38;5;241;43m*\u001b[39;49m\u001b[43mkwargs\u001b[49m\u001b[43m)\u001b[49m\n",
            "\u001b[0;31mFileNotFoundError\u001b[0m: [Errno 44] No such file or directory: 'test.txt'"
          ],
          "output_type": "error"
        }
      ],
      "execution_count": 4
    },
    {
      "cell_type": "code",
      "source": "#when there is a error in a code, we use esceptions handling with try and exceppt",
      "metadata": {
        "trusted": true
      },
      "outputs": [],
      "execution_count": 5
    },
    {
      "cell_type": "code",
      "source": "#exceptions Hand;ing blocks\n\ntry:\n    f = open(\"test.txt\" , 'r')\nexcept Exception as e :\n    print(\"this is myy except block\" , e)\n\n#first tryyy block will tryy to run the code given then if there is an error iin it, it will send iit to excepppt block, where thwre will exception class that wiill ahndle the error, yyou will still be able to run the code despite error in the giiven code",
      "metadata": {
        "trusted": true
      },
      "outputs": [
        {
          "name": "stdout",
          "text": "this is myy except block [Errno 44] No such file or directory: 'test.txt'\n",
          "output_type": "stream"
        }
      ],
      "execution_count": 6
    },
    {
      "cell_type": "code",
      "source": "#here we saw we still find the code work desppite there is isuue in it, it iiis because of exceptions handlings",
      "metadata": {
        "trusted": true
      },
      "outputs": [],
      "execution_count": 7
    },
    {
      "cell_type": "code",
      "source": "try:\n    f = open(\"test.txt\" , 'w')\n    f.write(\"write into myy file\")\n    f.close()\nexcept Exception as e :\n    print(\"this is myy except block\" , e)",
      "metadata": {
        "trusted": true
      },
      "outputs": [],
      "execution_count": 10
    },
    {
      "cell_type": "code",
      "source": "#in above code, we saw no use of except blockk because there was no error in thr original code",
      "metadata": {
        "trusted": true
      },
      "outputs": [],
      "execution_count": 11
    },
    {
      "cell_type": "code",
      "source": "#there are one more block after try and except blocks. except block can only work when there iis no error in the code or onece the tryyy block will excute withouut any error",
      "metadata": {
        "trusted": true
      },
      "outputs": [],
      "execution_count": 12
    },
    {
      "cell_type": "code",
      "source": "try:\n    f = open(\"test1.txt\" , 'w')\n    f.write(\"write into myy file\")\nexcept Exception as e :\n    print(\"this is myy except block\" , e)\nelse:\n    f.close()\n    print(\"thiis will be exceuted once yyyour try block will ecuted without error\")",
      "metadata": {
        "trusted": true
      },
      "outputs": [
        {
          "name": "stdout",
          "text": "thiis will be exceuted once yyyour try block will ecuted without error\n",
          "output_type": "stream"
        }
      ],
      "execution_count": 13
    },
    {
      "cell_type": "code",
      "source": "#$else block will only excuted when only try blockk succeffully excuted without anyyy error",
      "metadata": {
        "trusted": true
      },
      "outputs": [],
      "execution_count": 14
    },
    {
      "cell_type": "code",
      "source": "try:\n    f = open(\"test2.txt\" , 'r')\n    f.write(\"write into my file\")\nexcept Exception as e :\n    print(\"this is myy except block\" , e)\nelse:\n    f.close()\n    print(\"thiis will be exceuted once yyyour try block will ecuted without error\")",
      "metadata": {
        "trusted": true
      },
      "outputs": [
        {
          "name": "stdout",
          "text": "this is myy except block [Errno 44] No such file or directory: 'test2.txt'\n",
          "output_type": "stream"
        }
      ],
      "execution_count": 15
    },
    {
      "cell_type": "code",
      "source": "#here we cann see there is an erro iin the giiven code because we want to read the test2.txt file but there is no file crete dwith that nam,e, thats why there is error iin the coe,, itry block will pass iit to except block and will not go through else block",
      "metadata": {
        "trusted": true
      },
      "outputs": [],
      "execution_count": 16
    },
    {
      "cell_type": "code",
      "source": "#there is one block besiides try, except, else. it is called finally which will excute itself in anyys situatrion, iiit doesnt dependent on exceuteion f tyy block, even if there is error in try block there will be finallyy block excuted",
      "metadata": {
        "trusted": true
      },
      "outputs": [],
      "execution_count": 18
    },
    {
      "cell_type": "code",
      "source": "try :\n    f = open(\"test3.txt\" , 'w')\n    f.write(\"write ssomething\")\n    f.close()\n\nfinally :\n    print(\"finallyy will exceute itself iin any situuation\")",
      "metadata": {
        "trusted": true
      },
      "outputs": [
        {
          "name": "stdout",
          "text": "finallyy will exceute itself iin any situuation\n",
          "output_type": "stream"
        }
      ],
      "execution_count": 19
    },
    {
      "cell_type": "code",
      "source": "try :\n    f = open(\"test4.txt\" , 'r')\n    f.write(\"write ssomething\")\n    f.close()\n\nfinally :\n    print(\"finallyy will exceute itself iin any situuation\")",
      "metadata": {
        "trusted": true
      },
      "outputs": [
        {
          "name": "stdout",
          "text": "finallyy will exceute itself iin any situuation\n",
          "output_type": "stream"
        },
        {
          "ename": "<class 'FileNotFoundError'>",
          "evalue": "[Errno 44] No such file or directory: 'test4.txt'",
          "traceback": [
            "\u001b[0;31m---------------------------------------------------------------------------\u001b[0m",
            "\u001b[0;31mFileNotFoundError\u001b[0m                         Traceback (most recent call last)",
            "Cell \u001b[0;32mIn[20], line 2\u001b[0m\n\u001b[1;32m      1\u001b[0m \u001b[38;5;28;01mtry\u001b[39;00m :\n\u001b[0;32m----> 2\u001b[0m     f \u001b[38;5;241m=\u001b[39m \u001b[38;5;28;43mopen\u001b[39;49m\u001b[43m(\u001b[49m\u001b[38;5;124;43m\"\u001b[39;49m\u001b[38;5;124;43mtest4.txt\u001b[39;49m\u001b[38;5;124;43m\"\u001b[39;49m\u001b[43m \u001b[49m\u001b[43m,\u001b[49m\u001b[43m \u001b[49m\u001b[38;5;124;43m'\u001b[39;49m\u001b[38;5;124;43mr\u001b[39;49m\u001b[38;5;124;43m'\u001b[39;49m\u001b[43m)\u001b[49m\n\u001b[1;32m      3\u001b[0m     f\u001b[38;5;241m.\u001b[39mwrite(\u001b[38;5;124m\"\u001b[39m\u001b[38;5;124mwrite ssomething\u001b[39m\u001b[38;5;124m\"\u001b[39m)\n\u001b[1;32m      4\u001b[0m     f\u001b[38;5;241m.\u001b[39mclose()\n",
            "File \u001b[0;32m/lib/python3.11/site-packages/IPython/core/interactiveshell.py:310\u001b[0m, in \u001b[0;36m_modified_open\u001b[0;34m(file, *args, **kwargs)\u001b[0m\n\u001b[1;32m    303\u001b[0m \u001b[38;5;28;01mif\u001b[39;00m file \u001b[38;5;129;01min\u001b[39;00m {\u001b[38;5;241m0\u001b[39m, \u001b[38;5;241m1\u001b[39m, \u001b[38;5;241m2\u001b[39m}:\n\u001b[1;32m    304\u001b[0m     \u001b[38;5;28;01mraise\u001b[39;00m \u001b[38;5;167;01mValueError\u001b[39;00m(\n\u001b[1;32m    305\u001b[0m         \u001b[38;5;124mf\u001b[39m\u001b[38;5;124m\"\u001b[39m\u001b[38;5;124mIPython won\u001b[39m\u001b[38;5;124m'\u001b[39m\u001b[38;5;124mt let you open fd=\u001b[39m\u001b[38;5;132;01m{\u001b[39;00mfile\u001b[38;5;132;01m}\u001b[39;00m\u001b[38;5;124m by default \u001b[39m\u001b[38;5;124m\"\u001b[39m\n\u001b[1;32m    306\u001b[0m         \u001b[38;5;124m\"\u001b[39m\u001b[38;5;124mas it is likely to crash IPython. If you know what you are doing, \u001b[39m\u001b[38;5;124m\"\u001b[39m\n\u001b[1;32m    307\u001b[0m         \u001b[38;5;124m\"\u001b[39m\u001b[38;5;124myou can use builtins\u001b[39m\u001b[38;5;124m'\u001b[39m\u001b[38;5;124m open.\u001b[39m\u001b[38;5;124m\"\u001b[39m\n\u001b[1;32m    308\u001b[0m     )\n\u001b[0;32m--> 310\u001b[0m \u001b[38;5;28;01mreturn\u001b[39;00m \u001b[43mio_open\u001b[49m\u001b[43m(\u001b[49m\u001b[43mfile\u001b[49m\u001b[43m,\u001b[49m\u001b[43m \u001b[49m\u001b[38;5;241;43m*\u001b[39;49m\u001b[43margs\u001b[49m\u001b[43m,\u001b[49m\u001b[43m \u001b[49m\u001b[38;5;241;43m*\u001b[39;49m\u001b[38;5;241;43m*\u001b[39;49m\u001b[43mkwargs\u001b[49m\u001b[43m)\u001b[49m\n",
            "\u001b[0;31mFileNotFoundError\u001b[0m: [Errno 44] No such file or directory: 'test4.txt'"
          ],
          "output_type": "error"
        }
      ],
      "execution_count": 20
    },
    {
      "cell_type": "code",
      "source": "#here in above code, there is an error in try blcok but still the finally block is ecveuted successfully woithioiyt any dependenmce on try block or any other block",
      "metadata": {
        "trusted": true
      },
      "outputs": [],
      "execution_count": 21
    },
    {
      "cell_type": "code",
      "source": "#try, except, else and finally blocks should use regulary in evryy coding",
      "metadata": {
        "trusted": true
      },
      "outputs": [],
      "execution_count": null
    }
  ]
}